<?xml version="1.0"?>
<robot name="origins">

	<link name="base_link">
		<visual>
			<geometry>
				<mesh filename="package://virat_description/meshes/body/bot2.dae" />
			</geometry>
		</visual>
	</link>

	<link name="right_wheel">
		<visual>
			<geometry>
				<mesh filename="package://virat_description/meshes/wheels/tyre1.dae" />
			</geometry>
		</visual>
	</link>

	<joint name="right_axle" type="continuous">
		<axis rpy="0 0 0" xyz="0 1 0" />
		<parent link="base_link" />
		<child link="right_wheel" />
		<origin xyz="0 -0.323 0" />
	</joint>

	<link name="left_wheel">
		<visual>
			<geometry>
				<mesh filename="package://virat_description/meshes/wheels/tyre1.dae" />
			</geometry>
		</visual>
	</link>

	<joint name="left_axle" type="continuous">
		<axis rpy="0 0 0" xyz="0 1 0" />
		<parent link="base_link" />
		<child link="left_wheel" />
		<origin xyz="0 0.323 0" />
	</joint>

	<link name="front_castor">
		<visual>
			<geometry>
				<mesh filename="package://virat_description/meshes/wheels/castors1.dae" />
			</geometry>
		</visual>
	</link>

	<joint name="castor_joint" type="fixed">
		<parent link="base_link" />
		<child link="front_castor" />
		<origin xyz="0.48 0 0.02" />
	</joint>

</robot>