<?xml version="1.1"?>
<robot name="virat">

	<link name="dummy_link" />

	<joint name="base_joint" type="fixed">
		<parent link="dummy_link" />
		<child link="base_link" />
		<origin xyz="0 0 0" rpy="0 0 0" />
	</joint>

	<link name="base_link">
		<visual>
			<origin xyz="0 0 0" rpy="0 0 0" />
			<geometry>
				<mesh filename="package://virat_description/meshes/body/bot2.dae" />
			</geometry>
		</visual>

		<collision>
			<origin xyz="0 0 0" rpy="0 0 0" />
			<geometry>
				<mesh filename="package://virat_description/meshes/body/bot2.dae" />
			</geometry>
		</collision>

		<inertial>
			<origin xyz="0 0 0" rpy="0 0 0" />
			<mass value="1.5" />
			<inertia ixx="0.001" ixy="0" ixz="0" iyy="0.001" iyz="0" izz="0.001" />
		</inertial>
	</link>

	<link name="right_wheel_link">
		<visual>
			<origin xyz="0 0 0" rpy="0 0 0" />
			<geometry>
				<mesh filename="package://virat_description/meshes/wheels/tyre1.dae" />
			</geometry>
		</visual>

		<collision>
			<origin xyz="0 0 0" rpy="0 0 0" />
			<geometry>
				<mesh filename="package://virat_description/meshes/wheels/tyre1.dae" />
			</geometry>
		</collision>

		<inertial>
			<origin xyz="0 0 0" rpy="0 0 0" />
			<mass value="0.4" />
			<inertia ixx="0.001" ixy="0" ixz="0" iyy="0.001" iyz="0" izz="0.001" />
		</inertial>
	</link>

	<joint name="right_wheel_joint" type="continuous">
		<axis rpy="0 0 0" xyz="0 1 0" />
		<parent link="base_link" />
		<child link="right_wheel_link" />
		<origin xyz="0 -0.323 0" />
	</joint>

	<link name="left_wheel_link">
		<visual>
			<origin xyz="0 0 0" rpy="0 0 0" />
			<geometry>
				<mesh filename="package://virat_description/meshes/wheels/tyre1.dae" />
			</geometry>
		</visual>

		<collision>
			<origin xyz="0 0 0" rpy="0 0 0" />
			<geometry>
				<mesh filename="package://virat_description/meshes/wheels/tyre1.dae" />
			</geometry>
		</collision>

		<inertial>
			<origin xyz="0 0 0" rpy="0 0 0" />
			<mass value="0.4" />
			<inertia ixx="0.001" ixy="0" ixz="0" iyy="0.001" iyz="0" izz="0.001" />
		</inertial>
	</link>

	<joint name="left_wheel_joint" type="continuous">
		<axis rpy="0 0 0" xyz="0 1 0" />
		<parent link="base_link" />
		<child link="left_wheel_link" />
		<origin xyz="0 0.323 0" />
	</joint>

	<link name="front_castor_link">
		<visual>
			<origin xyz="0 0 0" rpy="0 0 0" />
			<geometry>
				<mesh filename="package://virat_description/meshes/wheels/castors1.dae" />
			</geometry>
		</visual>

		<collision>
			<origin xyz="0 0 0" rpy="0 0 0" />
			<geometry>
				<mesh filename="package://virat_description/meshes/wheels/castors1.dae" />
			</geometry>
		</collision>
		<inertial>
			<origin xyz="0 0 0" rpy="0 0 0" />
			<mass value="1" />
			<inertia ixx="0.001" ixy="0" ixz="0" iyy="0.001" iyz="0" izz="0.001" />
		</inertial>
	</link>

	<joint name="front_castor_joint" type="fixed">
		<parent link="base_link" />
		<child link="front_castor_link" />
		<origin xyz="0.48 0 0.02" />
	</joint>

	<link name="camera_link">
		<visual>
			<origin xyz="0 0 0" rpy="0 0 0" />
			<geometry>
				<box size="0.05 0.05 0.05" />
			</geometry>
		</visual>
	</link>

	<joint name="camera_joint" type="fixed">
		<parent link="base_link" />
		<child link="camera_link" />
		<origin xyz="0.73 0 1.18" rpy="0 0.45 0" />
	</joint>

	<gazebo>
		<plugin filename="libgazebo_ros_diff_drive.so" name="differential_drive_controller">
			<alwaysOn>true</alwaysOn>
			<updateRate>20</updateRate>
			<leftJoint>left_wheel_joint</leftJoint>
			<rightJoint>right_wheel_joint</rightJoint>
			<wheelSeparation>0.626</wheelSeparation>
			<wheelDiameter>0.4</wheelDiameter>
			<torque>1.0</torque>
			<commandTopic>virat/cmd_vel</commandTopic>
			<odometryTopic>virat/odom</odometryTopic>
			<odometryFrame>odom</odometryFrame>
			<robotBaseFrame>base_link</robotBaseFrame>
		</plugin>
	</gazebo>

	<gazebo reference="camera_link">
		<sensor type="camera" name="camera_top">
			<update_rate>30.0</update_rate>
			<camera name="top">
				<horizontal_fov>1.3962634</horizontal_fov>
				<image>
					<width>800</width>
					<height>800</height>
					<format>R8G8B8</format>
				</image>
				<clip>
					<near>0.02</near>
					<far>300</far>
				</clip>
				<noise>
					<type>gaussian</type>
					<!-- Noise is sampled independently per pixel on each frame. That pixel's noise value is added to each of its color channels, which at that point lie in the range [0,1]. -->
					<mean>0.0</mean>
					<stddev>0.007</stddev>
				</noise>
			</camera>
			<plugin name="camera_controller" filename="libgazebo_ros_camera.so">
				<alwaysOn>true</alwaysOn>
				<updateRate>0.0</updateRate>
				<cameraName>virat/camera_top</cameraName>
				<imageTopicName>image_raw</imageTopicName>
				<cameraInfoTopicName>camera_info</cameraInfoTopicName>
				<frameName>camera_link</frameName>
				<hackBaseline>0.07</hackBaseline>
				<distortionK1>0.0</distortionK1>
				<distortionK2>0.0</distortionK2>
				<distortionK3>0.0</distortionK3>
				<distortionT1>0.0</distortionT1>
				<distortionT2>0.0</distortionT2>
			</plugin>
		</sensor>
	</gazebo>

	<gazebo reference="camera_link">
		<material>
			Gazebo/BlueGlow
		</material>
	</gazebo>

</robot>