<?xml version="1.0"?>
<robot name="virat">

	<link name="base_footprint" />

	<joint name="base_joint" type="fixed">
		<parent link="base_footprint" />
		<child link="base_link" />
		<origin xyz="0 0 0" rpy="0 0 0" />
	</joint>

	<link name="base_link">
		<visual>
			<origin xyz="0 0 0" rpy="0 0 0" />
			<geometry>
				<mesh filename="package://virat_description/meshes/body/bot2.dae" />
			</geometry>
		</visual>

		<collision>
			<origin xyz="0 0 0" rpy="0 0 0" />
			<geometry>
				<mesh filename="package://virat_description/meshes/body/bot2.dae" />
			</geometry>
		</collision>

		<inertial>
			<origin xyz="0 0 0" rpy="0 0 0" />
			<mass value="6.0" />
			<inertia ixx="4.0" ixy="-1" ixz="-1.0" iyy="8.0" iyz="0.0" izz="6.0" />
		</inertial>
	</link>

	<link name="right_wheel_link">
		<visual>
			<origin xyz="0 0 0" rpy="0 0 0" />
			<geometry>
				<mesh filename="package://virat_description/meshes/wheels/tyre1.dae" />
			</geometry>
		</visual>

		<collision>
			<origin xyz="0 0 0" rpy="0 0 0" />
			<geometry>
				<mesh filename="package://virat_description/meshes/wheels/tyre1.dae" />
			</geometry>
		</collision>

		<inertial>
			<origin xyz="0 0 0" rpy="0 0 0" />
			<mass value="1.0" />
			<inertia ixx="0.25" ixy="0.0" ixz="0.0" iyy="0.5" iyz="0.0" izz="0.25" />
		</inertial>
	</link>

	<joint name="right_wheel_joint" type="continuous">
		<axis rpy="0 0 0" xyz="0 1 0" />
		<parent link="base_link" />
		<child link="right_wheel_link" />
		<origin xyz="0 -0.323 0" />
	</joint>

	<link name="left_wheel_link">
		<visual>
			<origin xyz="0 0 0" rpy="0 0 0" />
			<geometry>
				<mesh filename="package://virat_description/meshes/wheels/tyre1.dae" />
			</geometry>
		</visual>

		<collision>
			<origin xyz="0 0 0" rpy="0 0 0" />
			<geometry>
				<mesh filename="package://virat_description/meshes/wheels/tyre1.dae" />
			</geometry>
		</collision>

		<inertial>
			<origin xyz="0 0 0" rpy="0 0 0" />
			<mass value="1.0" />
			<inertia ixx="0.25" ixy="0.0" ixz="0.0" iyy="0.5" iyz="0.0" izz="0.25" />
		</inertial>
	</link>

	<joint name="left_wheel_joint" type="continuous">
		<axis rpy="0 0 0" xyz="0 1 0" />
		<parent link="base_link" />
		<child link="left_wheel_link" />
		<origin xyz="0 0.323 0" />
	</joint>

	<link name="front_castor_link">
		<visual>
			<origin xyz="0 0 0" rpy="0 0 0" />
			<geometry>
				<mesh filename="package://virat_description/meshes/wheels/castors1.dae" />
			</geometry>
		</visual>

		<collision>
			<origin xyz="0 0 0" rpy="0 0 0" />
			<geometry>
				<mesh filename="package://virat_description/meshes/wheels/castors1.dae" />
			</geometry>
		</collision>
		<inertial>
			<origin xyz="0 0 0" rpy="0 0 0" />
			<mass value="0.2" />
			<inertia ixx="0.05" ixy="0.0" ixz="0.0" iyy="0.1" iyz="0.0" izz="0.05" />
		</inertial>
	</link>

	<joint name="front_castor_joint" type="fixed">
		<parent link="base_link" />
		<child link="front_castor_link" />
		<origin xyz="0.48 0 0.02" />
	</joint>

</robot>